<?xml version="1.0" ?>
<!-- =================================================================================== -->
<!-- |    This document was autogenerated by xacro from iirbot.urdf.xacro              | -->
<!-- |    EDITING THIS FILE BY HAND IS NOT RECOMMENDED                                 | -->
<!-- =================================================================================== -->
<!-- Basic differential drive mobile base -->
<robot name="iirbot">
  <material name="black">
    <color rgba="0.0 0.0 0.0 1.0"/>
  </material>
  <material name="blue">
    <color rgba="0.0 0.0 0.8 1.0"/>
  </material>
  <material name="green">
    <color rgba="0.0 0.8 0.0 1.0"/>
  </material>
  <material name="grey">
    <color rgba="0.2 0.2 0.2 1.0"/>
  </material>
  <material name="orange">
    <color rgba="1.0 0.4235294117647059 0.0392156862745098 1.0"/>
  </material>
  <material name="brown">
    <color rgba="0.8705882352941177 0.8117647058823529 0.7647058823529411 1.0"/>
  </material>
  <material name="red">
    <color rgba="0.8 0.0 0.0 1.0"/>
  </material>
  <material name="white">
    <color rgba="1.0 1.0 1.0 1.0"/>
  </material>
  <!-- Space btw top of beam and the each joint -->
  <!-- Base Link -->
  <link name="_base_link">
    <collision>
      <origin rpy="0 0 0" xyz="0 0 0"/>
      <geometry>
        <box size="0.63 0.57 0.17"/>
      </geometry>
    </collision>
    <visual>
      <origin rpy="0 0 0" xyz="0 0 0.085"/>
      <geometry>
        <box size="0.63 0.57 0.17"/>
      </geometry>
      <material name="orange"/>
    </visual>
    <inertial>
      <origin rpy="0 0 0" xyz="0 0 0"/>
      <mass value="0.3"/>
      <inertia ixx="0.008844999999999999" ixy="0.0" ixz="0.0" iyy="0.010645" iyz="0.0" izz="0.018045"/>
    </inertial>
  </link>
  <joint name="_left_wheel_joint" type="continuous">
    <parent link="_base_link"/>
    <child link="_left_wheel"/>
    <origin rpy="0 0 0" xyz="0 -.45 -0.085"/>
    <axis xyz="0 1 0"/>
    <dynamics damping="0.2"/>
    <limit effort="100" velocity="1.0"/>
  </joint>
  <!-- left wheel Link -->
  <link name="_left_wheel">
    <collision>
      <origin rpy="1.5707963267948966 0 0" xyz="0 0 0"/>
      <geometry>
        <cylinder length="0.02" radius="0.05"/>
      </geometry>
    </collision>
    <visual>
      <origin rpy="1.5707963267948966 0 0" xyz="0 0 0"/>
      <geometry>
        <cylinder length="0.02" radius="0.05"/>
      </geometry>
      <material name="black"/>
    </visual>
    <inertial>
      <origin rpy="1.5707963267948966 0 0" xyz="0 0 0"/>
      <mass value="0.3"/>
      <inertia ixx="0.0001975" ixy="0.0" ixz="0.0" iyy="0.0001975" iyz="0.0" izz="0.000375"/>
    </inertial>
  </link>
  <joint name="_right_wheel_joint" type="continuous">
    <parent link="_base_link"/>
    <child link="_right_wheel"/>
    <origin rpy="0 0 0" xyz="0 .45 -0.085"/>
    <axis xyz="0 1 0"/>
    <dynamics damping="0.2"/>
    <limit effort="100" velocity="1.0"/>
  </joint>
  <!-- right wheel Link -->
  <link name="_right_wheel">
    <collision>
      <origin rpy="1.5707963267948966 0 0" xyz="0 0 0"/>
      <geometry>
        <cylinder length="0.02" radius="0.05"/>
      </geometry>
    </collision>
    <visual>
      <origin rpy="1.5707963267948966 0 0" xyz="0 0 0"/>
      <geometry>
        <cylinder length="0.02" radius="0.05"/>
      </geometry>
      <material name="black"/>
    </visual>
    <inertial>
      <origin rpy="1.5707963267948966 0 0" xyz="0 0 0"/>
      <mass value="0.3"/>
      <inertia ixx="0.0001975" ixy="0.0" ixz="0.0" iyy="0.0001975" iyz="0.0" izz="0.000375"/>
    </inertial>
  </link>
  <joint name="_caster_frontal_wheel_joint" type="fixed">
    <parent link="_base_link"/>
    <child link="_caster_frontal_wheel"/>
    <origin rpy="0 0 0" xyz="0.3 0 -0.085"/>
  </joint>
  <!-- caster frontal wheel Link -->
  <link name="_caster_frontal_wheel">
    <collision>
      <origin rpy="0 0 0" xyz="0 0 0"/>
      <geometry>
        <sphere radius="0.015"/>
      </geometry>
    </collision>
    <visual>
      <origin rpy="0 0 0" xyz="0 0 0"/>
      <geometry>
        <sphere radius="0.015"/>
      </geometry>
      <material name="white"/>
    </visual>
    <inertial>
      <origin rpy="0 0 0" xyz="0 0 0"/>
      <mass value="0.1"/>
      <inertia ixx="9.000000000000002e-06" ixy="0.0" ixz="0.0" iyy="9.000000000000002e-06" iyz="0.0" izz="9.000000000000002e-06"/>
    </inertial>
  </link>
  <joint name="_caster_rear_wheel_joint" type="fixed">
    <parent link="_base_link"/>
    <child link="_caster_rear_wheel"/>
    <origin rpy="0 0 0" xyz="-0.3 0 -0.085"/>
  </joint>
  <!-- caster rear wheel Link -->
  <link name="_caster_rear_wheel">
    <collision>
      <origin rpy="0 0 0" xyz="0 0 0"/>
      <geometry>
        <sphere radius="0.015"/>
      </geometry>
    </collision>
    <visual>
      <origin rpy="0 0 0" xyz="0 0 0"/>
      <geometry>
        <sphere radius="0.015"/>
      </geometry>
      <material name="white"/>
    </visual>
    <inertial>
      <origin rpy="0 0 0" xyz="0 0 0"/>
      <mass value="0.1"/>
      <inertia ixx="9.000000000000002e-06" ixy="0.0" ixz="0.0" iyy="9.000000000000002e-06" iyz="0.0" izz="9.000000000000002e-06"/>
    </inertial>
  </link>
  <ros2_control name="IirBot" type="system">
    <hardware>
      <plugin>diff_drive_controller/DiffBotSystemHardware</plugin>
      <param name="example_param_hw_start_duration_sec">0</param>
      <param name="example_param_hw_stop_duration_sec">3.0</param>
    </hardware>
    <joint name="_left_wheel_joint">
      <command_interface name="velocity"/>
      <state_interface name="position"/>
      <state_interface name="velocity"/>
    </joint>
    <joint name="_right_wheel_joint">
      <command_interface name="velocity"/>
      <state_interface name="position"/>
      <state_interface name="velocity"/>
    </joint>
  </ros2_control>
</robot>
